Workbook
Name DF_GRID_1: Mapa!$D$9:$K$73
Name DF_GRID_2: Despesa - Dot [1]Disponível!$F$13:$L$14
Name DF_GRID_3: Receita - Dot [2]Corrigida!$F$13:$L$14
Name DF_GRID_4: Despesa - Dot [1]Disponível!$F$21:$L$22

Sheet BExRepositorySheet
A1: 7

Sheet Mapa
B2: FV
A3: 5.1.1.1.6 - Plan. dos OBJ, ACT, ACC e EAC
D7: 21-04-2017 | F7: Última atualização
K9: Resultado global
K10: Dotação | M10: Recursos utilizados 2022 | R10: Recursos utilizados 2023
D11: Objectivo | E11: Tipo de Atividade | F11: Actividade PA | G11: Acção | H11: Elemento de Acção | I11: Económica Despesa Legal | K11: 2022 | L11: 2023 | M11: Of | N11: Alun | O11: Sarg | P11: Pr | Q11: Civis | R11: Of | S11: Alun | T11: Sarg | U11: Pr | V11: Civis
D12: 00 21 Aumentar particip sociedade atividades Exército | E12: Ensino | F12: Reforçar a afirmação e a ligação da AM à sociedade | G12: Formação em Liderança | H12: Ação de formação em Liderança à CGD (5 dias) | I12: 02.01.05 | J12: Alimentação-Refeições confeccionadas | K12: 4000 | L12: 4000 | M12: 2 | N12: 0 | O12: 2 | P12: 1 | Q12: 2 | R12: 3 | S12: 0 | T12: 3 | U12: 2 | V12: 2
D13: 00 21 Aumentar particip sociedade atividades Exército | E13: Ensino | F13: Reforçar a afirmação e a ligação da AM à sociedade | G13: Formação em Liderança | H13: Ação de formação em Liderança à CGD (5 dias) | I13: 02.01.06 | J13: Alimentação-Géneros pª confeccionar | K13: 8000 | L13: 7500
D14: 00 21 Aumentar particip sociedade atividades Exército | E14: Ensino | F14: Reforçar a afirmação e a ligação da AM à sociedade | G14: Formação em Liderança | H14: Ação de formação em Liderança à CGD (5 dias) | I14: 02.01.08.C0.00 | J14: Material de Escritório - Outros | K14: 500 | L14: 600
D15: 00 21 Aumentar particip sociedade atividades Exército | E15: Ensino | F15: Reforçar a afirmação e a ligação da AM à sociedade | G15: Formação em Liderança | H15: Ação de formação em Liderança à CGD (5 dias) | I15: 02.01.15 | J15: Prémios, condecorações e ofertas | K15: 2000 | L15: 1900
D16: 00 21 Aumentar particip sociedade atividades Exército | E16: Ensino | F16: Reforçar a afirmação e a ligação da AM à sociedade | G16: Formação em Liderança | H16: Ação de formação em Liderança à CGD (5 dias) | I16: 02.01.19 | J16: Artigos honoríficos e de decoração | K16: 5000 | L16: 4750
D17: 00 21 Aumentar particip sociedade atividades Exército | E17: Ensino | F17: Reforçar a afirmação e a ligação da AM à sociedade | G17: Formação em Liderança | H17: Ação de formação em Liderança à CGD (5 dias) | I17: 02.01.21 | J17: Outros bens | K17: 175 | L17: 200
D18: 00 21 Aumentar particip sociedade atividades Exército | E18: Ensino | F18: Reforçar a afirmação e a ligação da AM à sociedade | G18: Formação em Liderança | H18: Ação de formação em Liderança à CGD (5 dias) | I18: 02.02.17 | J18: Publicidade | K18: 500 | L18: 600
E19: Ensino | F19: Reforçar a afirmação e a ligação da AM à sociedade | G19: Formação em Liderança | H19: Ação de formação em Liderança à ANJE (5 dias) | I19: 02.01.05 | J19: Alimentação-Refeições confeccionadas | K19: 4000 | L19: 4000 | M19: 2 | N19: 0 | O19: 2 | P19: 1 | Q19: 2 | R19: 4 | S19: 0 | T19: 3 | U19: 4 | V19: 2
E20: Ensino | F20: Reforçar a afirmação e a ligação da AM à sociedade | G20: Formação em Liderança | H20: Ação de formação em Liderança à ANJE (5 dias) | I20: 02.01.06 | J20: Alimentação-Géneros pª confeccionar | K20: 8000 | L20: 7500
E21: Ensino | F21: Reforçar a afirmação e a ligação da AM à sociedade | G21: Formação em Liderança | H21: Ação de formação em Liderança à ANJE (5 dias) | I21: 02.01.08.C0.00 | J21: Material de Escritório - Outros | K21: 500 | L21: 600
E22: Ensino | F22: Reforçar a afirmação e a ligação da AM à sociedade | G22: Formação em Liderança | H22: Ação de formação em Liderança à ANJE (5 dias) | I22: 02.01.15 | J22: Prémios, condecorações e ofertas | K22: 2000 | L22: 1900
E23: Ensino | F23: Reforçar a afirmação e a ligação da AM à sociedade | G23: Formação em Liderança | H23: Ação de formação em Liderança à ANJE (5 dias) | I23: 02.01.19 | J23: Artigos honoríficos e de decoração | K23: 5000 | L23: 4750
E24: Ensino | F24: Reforçar a afirmação e a ligação da AM à sociedade | G24: Formação em Liderança | H24: Ação de formação em Liderança à ANJE (5 dias) | I24: 02.01.21 | J24: Outros bens | K24: 175 | L24: 200
E25: Ensino | F25: Reforçar a afirmação e a ligação da AM à sociedade | G25: Formação em Liderança | H25: Ação de formação em Liderança à ANJE (5 dias) | I25: 02.02.17 | J25: Publicidade | K25: 500 | L25: 600
D26: 00 22 Ampliar quant tipologia ativid Ex destinadas cidadãos | E26: Formação | F26: Integrar a formação científica, militar e comportamental | G26: Cerimónias Militares e Actividades Culturais do CAl | H26: Cerimónias Militares e Actividades Culturais do CAl | I26: 02.01.06 | J26: Alimentação-Géneros pª confeccionar | K26: 200 | L26: 300 | M26: 10 cerimónias | R26: 11 cerimónias
D27: 00 22 Ampliar quant tipologia ativid Ex destinadas cidadãos | E27: Formação | F27: Integrar a formação científica, militar e comportamental | G27: Cerimónias Militares e Actividades Culturais do CAl | H27: Cerimónias Militares e Actividades Culturais do CAl | I27: 02.01.08.C0.00 | J27: Material de Escritório - Outros | K27: 250 | L27: 250
D28: 00 22 Ampliar quant tipologia ativid Ex destinadas cidadãos | E28: Formação | F28: Integrar a formação científica, militar e comportamental | G28: Cerimónias Militares e Actividades Culturais do CAl | H28: Cerimónias Militares e Actividades Culturais do CAl | I28: 02.02.21 | J28: Utilização de infra-estruturas de transportes | K28: 500 | L28: 500
D29: 00 22 Ampliar quant tipologia ativid Ex destinadas cidadãos | E29: Formação | F29: Integrar a formação científica, militar e comportamental | G29: Cerimónias Militares e Actividades Culturais do CAl | H29: Cerimónias Militares e Actividades Culturais do CAl | I29: 02.02.25 | J29: Outros serviços | K29: 800 | L29: 1500
D30: 00 31 Aumentar as forças e o pessoal treinado e certificado | E30: Formação | F30: Integrar a formação científica, militar e comportamental | G30: Cursos para não docentes do CAl | H30: Cursos para não docentes do CAl | I30: 02.01.08.C0.00 | J30: Material de Escritório - Outros | K30: 500 | L30: 500 | O30: 2 | T30: 2
D31: 00 31 Aumentar as forças e o pessoal treinado e certificado | E31: Formação | F31: Integrar a formação científica, militar e comportamental | G31: Cursos para não docentes do CAl | H31: Cursos para não docentes do CAl | I31: 02.01.21 | J31: Outros bens | K31: 250 | L31: 250
D32: 00 31 Aumentar as forças e o pessoal treinado e certificado | E32: Formação | F32: Integrar a formação científica, militar e comportamental | G32: Cursos para não docentes do CAl | H32: Cursos para não docentes do CAl | I32: 02.02.13 | J32: Deslocações e estadas | K32: 2150 | L32: 2150
D33: 00 31 Aumentar as forças e o pessoal treinado e certificado | E33: Formação | F33: Integrar a formação científica, militar e comportamental | G33: Cursos para não docentes do CAl | H33: Cursos para não docentes do CAl | I33: 02.02.21 | J33: Utilização de infra-estruturas de transportes | K33: 1250 | L33: 1250
D34: 00 31 Aumentar as forças e o pessoal treinado e certificado | E34: Formação | F34: Integrar a formação científica, militar e comportamental | G34: Cursos para docentes do CAl | H34: Cursos para docentes do CAl | I34: 02.02.15.B0.00 | J34: Formação - Outras | K34: 2500 | L34: 5500 | M34: 1 | R34: 2
D35: 00 31 Aumentar as forças e o pessoal treinado e certificado | E35: Formação | F35: Integrar a formação científica, militar e comportamental | G35: Formação Militar e Exercícios | H35: BFM2 | I35: 02.01.08.C0.00 | J35: Material de Escritório - Outros | K35: 5000 | L35: 4500 | M35: 8 | N35: 200 | O35: 1 | P35: 5 | Q35: 2 | R35: 8 | S35: 250 | T35: 1 | U35: 5 | V35: 2
D36: 00 31 Aumentar as forças e o pessoal treinado e certificado | E36: Formação | F36: Integrar a formação científica, militar e comportamental | G36: Formação Militar e Exercícios | H36: BFM2 | I36: 02.01.21 | J36: Outros bens | K36: 1700 | L36: 1500
D37: 00 31 Aumentar as forças e o pessoal treinado e certificado | E37: Formação | F37: Integrar a formação científica, militar e comportamental | G37: Formação Militar e Exercícios | H37: BFM2 | I37: 02.02.10 | J37: Transportes | K37: 5000 | L37: 5000
D38: 00 31 Aumentar as forças e o pessoal treinado e certificado | E38: Formação | F38: Integrar a formação científica, militar e comportamental | G38: Formação Militar e Exercícios | H38: BFM2 | I38: 02.02.21 | J38: Utilização de infra-estruturas de transportes | K38: 1200 | L38: 1000
D39: 00 31 Aumentar as forças e o pessoal treinado e certificado | E39: Formação | F39: Integrar a formação científica, militar e comportamental | G39: Formação Militar e Exercícios | H39: BFM3 | I39: 02.01.08.C0.00 | J39: Material de Escritório - Outros | K39: 5000 | L39: 5000 | M39: 8 | N39: 200 | O39: 1 | P39: 5 | Q39: 2 | R39: 8 | S39: 250 | T39: 1 | U39: 5 | V39: 2
D40: 00 31 Aumentar as forças e o pessoal treinado e certificado | E40: Formação | F40: Integrar a formação científica, militar e comportamental | G40: Formação Militar e Exercícios | H40: BFM3 | I40: 02.01.21 | J40: Outros bens | K40: 1700 | L40: 1700
D41: 00 31 Aumentar as forças e o pessoal treinado e certificado | E41: Formação | F41: Integrar a formação científica, militar e comportamental | G41: Formação Militar e Exercícios | H41: BFM3 | I41: 02.02.10 | J41: Transportes | K41: 29100 | L41: 40000
D42: 00 31 Aumentar as forças e o pessoal treinado e certificado | E42: Formação | F42: Integrar a formação científica, militar e comportamental | G42: Formação Militar e Exercícios | H42: BFM3 | I42: 02.02.21 | J42: Utilização de infra-estruturas de transportes | K42: 1200 | L42: 1200
D43: 00 31 Aumentar as forças e o pessoal treinado e certificado | E43: Formação | F43: Integrar a formação científica, militar e comportamental | G43: Cerimónias Militares e Actividades Culturais do CAl | H43: Baile de finalistas | I43: 02.01.05 | J43: Alimentação-Refeições confeccionadas | K43: 12000 | L43: 12000 | M43: 25 | N43: 200 | O43: 1 | P43: 3 | Q43: 10 | R43: 15 | S43: 250 | T43: 1 | U43: 3 | V43: 10
D44: 00 31 Aumentar as forças e o pessoal treinado e certificado | E44: Formação | F44: Integrar a formação científica, militar e comportamental | G44: Cerimónias Militares e Actividades Culturais do CAl | H44: Baile de finalistas | I44: 02.01.06 | J44: Alimentação-Géneros pª confeccionar | K44: 600 | L44: 600
D45: 00 31 Aumentar as forças e o pessoal treinado e certificado | E45: Formação | F45: Integrar a formação científica, militar e comportamental | G45: Cerimónias Militares e Actividades Culturais do CAl | H45: Baile de finalistas | I45: 02.01.15 | J45: Prémios, condecorações e ofertas | K45: 1500 | L45: 1500
...

Sheet Outros
A1: Ano | B1: Orçamento total | C1: Atividades | D1: Orçamento parcial | E1: Outputs | F1: Inquérito Grau satisfação (1 - Mau a 5 - Muito bom)
F2: Média
A3: 2022 | B3: =Mapa!K74 -> 1429069 | C3: Formação | D3: =Mapa!K26+Mapa!K27+Mapa!K28+Mapa!K29+Mapa!K30+Mapa!K31+Mapa!K32+Mapa!K33+Mapa!K34+Mapa!K35+Mapa!K36+Mapa!K37+Mapa!K38+Mapa!K39+Mapa!K40+Mapa!K41+Mapa!K42+Mapa!K43+Mapa!K44+Mapa!K45+Mapa!K46+Mapa!K47+Mapa!K48+Mapa!K49+Mapa!K50+Mapa!K51 -> 108400 | E3: 110 alunos | F3: 4.1
C4: Investigação | D4: =Mapa!K55+Mapa!K71+Mapa!K72+Mapa!K73 -> 10637 | F4: 3.8
C5: Ensino | D5: =Mapa!K12+Mapa!K13+Mapa!K14+Mapa!K15+Mapa!K16+Mapa!K17+Mapa!K18+Mapa!K19+Mapa!K20+Mapa!K21+Mapa!K22+Mapa!K23+Mapa!K24+Mapa!K25+Mapa!K52+Mapa!K53+Mapa!K54 -> 62591 | F5: 4.1
C6: Vida Corrente | D6: =B3-D3-D4-D5 -> 1247441 | F6: 3.8
A7: 2023 | B7: =Mapa!L74 -> 1646150.3 | C7: Formação | D7: =Mapa!L26+Mapa!L27+Mapa!L28+Mapa!L29+Mapa!L30+Mapa!L31+Mapa!L32+Mapa!L33+Mapa!L34+Mapa!L35+Mapa!L36+Mapa!L37+Mapa!L38+Mapa!L39+Mapa!L40+Mapa!L41+Mapa!L42+Mapa!L43+Mapa!L44+Mapa!L45+Mapa!L46+Mapa!L47+Mapa!L48+Mapa!L49+Mapa!L50+Mapa!L51 -> 133700 | E7: 140 alunos | F7: 4.1
C8: Investigação | D8: =Mapa!L55+Mapa!L71+Mapa!L72+Mapa!L73 -> 12043.85 | F8: 4.1
C9: Ensino | D9: =Mapa!L12+Mapa!L13+Mapa!L14+Mapa!L15+Mapa!L16+Mapa!L17+Mapa!L18+Mapa!L19+Mapa!L20+Mapa!L21+Mapa!L22+Mapa!L23+Mapa!L24+Mapa!L25+Mapa!L52+Mapa!L53+Mapa!L54 -> 66850 | F9: 4.4
C10: Vida Corrente | D10: =B7-D7-D8-D9 -> 1433556.5 | F10: 3.8
